Workbook
Name a: Sheet1!$K$7:$N$22
Name impossible: calcs!$E$1
Name team_map_no_initials: [1]TeamMap!$A$34:$B$63

Sheet Sheet1
K1: Michigan can win a game in regular time, not make-believe time…
K2: =IF(COUNTA(INDIRECT("K7:N"&O2))>6,"Too Many Picks!",IF(COUNTIF(INDIRECT("O7:O"&O2),"Error!")>0,"ERROR!",IF(COUNTA(INDIRECT("K7:N"&O2))=6,"Perfect!",6-COUNTA(INDIRECT("K7:N"&O2))&" Picks Left"))) -> 6 Picks Left | O2: =6+COUNTA(B7:B22) -> 22
B4: 2026 NFL Season: Week 1
H6: Line | I6: O / U | K6: Away | L6: Home | M6: Under | N6: Over | P6: Submission rules:
B7: Wed, 7:20pm; *NBC | D7: Lumen Field | E7: New England Patriots | F7: @ | G7: Seattle Seahawks | H7: -3.5 | I7: 44.5 | O7: =IF(OR(COUNTA(K7:L7)=2,COUNTA(M7:N7)=2,AND(ISBLANK(B7),COUNTA(K7:N7)>0),AND(H7="OFF",COUNTA(K7:L7)>0),AND(I7="OFF",COUNTA(M7:N7)>0)),"Error!","") | Q7: Your picks are independently locked in when each game starts.
B8: Thu, 7:35pm; Netflix | D8: Melbourne Cricket Ground | E8: San Francisco 49ers | F8: @ | G8: Los Angeles Rams | H8: -3.5 | I8: 48.5 | O8: =IF(OR(COUNTA(K8:L8)=2,COUNTA(M8:N8)=2,AND(ISBLANK(B8),COUNTA(K8:N8)>0),AND(H8="OFF",COUNTA(K8:L8)>0),AND(I8="OFF",COUNTA(M8:N8)>0)),"Error!","") | Q8: A pick may be made or changed by any means of communication with these conditions:
B9: Sun, 12:00pm; FOX | D9: Paycor Stadium | E9: Tampa Bay Buccaneers | F9: @ | G9: Cincinnati Bengals | H9: -3.5 | I9: 50.5 | O9: =IF(OR(COUNTA(K9:L9)=2,COUNTA(M9:N9)=2,AND(ISBLANK(B9),COUNTA(K9:N9)>0),AND(H9="OFF",COUNTA(K9:L9)>0),AND(I9="OFF",COUNTA(M9:N9)>0)),"Error!","") | R9: - The timestamp is confirmable
B10: Sun, 12:00pm; FOX | D10: Ford Field | E10: New Orleans Saints | F10: @ | G10: Detroit Lions | H10: -7 | I10: 49.5 | O10: =IF(OR(COUNTA(K10:L10)=2,COUNTA(M10:N10)=2,AND(ISBLANK(B10),COUNTA(K10:N10)>0),AND(H10="OFF",COUNTA(K10:L10)>0),AND(I10="OFF",COUNTA(M10:N10)>0)),"Error!","") | R10: - The pick or change is consistent with all rules and valid with your other selections
B11: Sun, 12:00pm; CBS | D11: Nissan Stadium | E11: New York Jets | F11: @ | G11: Tennessee Titans | H11: -1.5 | I11: 39.5 | O11: =IF(OR(COUNTA(K11:L11)=2,COUNTA(M11:N11)=2,AND(ISBLANK(B11),COUNTA(K11:N11)>0),AND(H11="OFF",COUNTA(K11:L11)>0),AND(I11="OFF",COUNTA(M11:N11)>0)),"Error!","") | R11: - The pick or change must be communicated unambiguously
B12: Sun, 12:00pm; CBS | D12: Lucas Oil Stadium | E12: Baltimore Ravens | F12: @ | G12: Indianapolis Colts | H12: 3 | I12: 47.5 | O12: =IF(OR(COUNTA(K12:L12)=2,COUNTA(M12:N12)=2,AND(ISBLANK(B12),COUNTA(K12:N12)>0),AND(H12="OFF",COUNTA(K12:L12)>0),AND(I12="OFF",COUNTA(M12:N12)>0)),"Error!","") | R12: - You send an updated pick spreadsheet Monday or Tuesday morning, when possible
B13: Sun, 12:00pm; FOX | D13: Acrisure Stadium | E13: Atlanta Falcons | F13: @ | G13: Pittsburgh Steelers | H13: -3.5 | I13: 42.5 | O13: =IF(OR(COUNTA(K13:L13)=2,COUNTA(M13:N13)=2,AND(ISBLANK(B13),COUNTA(K13:N13)>0),AND(H13="OFF",COUNTA(K13:L13)>0),AND(I13="OFF",COUNTA(M13:N13)>0)),"Error!","")
B14: Sun, 12:00pm; FOX | D14: Bank of America Stadium | E14: Chicago Bears | F14: @ | G14: Carolina Panthers | H14: 3 | I14: 46.5 | O14: =IF(OR(COUNTA(K14:L14)=2,COUNTA(M14:N14)=2,AND(ISBLANK(B14),COUNTA(K14:N14)>0),AND(H14="OFF",COUNTA(K14:L14)>0),AND(I14="OFF",COUNTA(M14:N14)>0)),"Error!","") | Q14: *Games airing on TV in Minneapolis/St. Paul broadcast area
B15: Sun, 12:00pm; CBS | D15: EverBank Stadium | E15: Cleveland Browns | F15: @ | G15: Jacksonville Jaguars | H15: -7.5 | I15: 40.5 | O15: =IF(OR(COUNTA(K15:L15)=2,COUNTA(M15:N15)=2,AND(ISBLANK(B15),COUNTA(K15:N15)>0),AND(H15="OFF",COUNTA(K15:L15)>0),AND(I15="OFF",COUNTA(M15:N15)>0)),"Error!","")
B16: Sun, 12:00pm; CBS | D16: Reliant Stadium | E16: Buffalo Bills | F16: @ | G16: Houston Texans | H16: 1.5 | I16: 44.5 | O16: =IF(OR(COUNTA(K16:L16)=2,COUNTA(M16:N16)=2,AND(ISBLANK(B16),COUNTA(K16:N16)>0),AND(H16="OFF",COUNTA(K16:L16)>0),AND(I16="OFF",COUNTA(M16:N16)>0)),"Error!","") | P16: michael@shouper.com
B17: Sun, 3:25pm; FOX | D17: Allegiant Stadium | E17: Miami Dolphins | F17: @ | G17: Las Vegas Raiders | H17: -3.5 | I17: 40.5 | O17: =IF(OR(COUNTA(K17:L17)=2,COUNTA(M17:N17)=2,AND(ISBLANK(B17),COUNTA(K17:N17)>0),AND(H17="OFF",COUNTA(K17:L17)>0),AND(I17="OFF",COUNTA(M17:N17)>0)),"Error!","") | P17: michael.e.shoup@ampf.com
B18: Sun, 3:25pm; *CBS | D18: U.S. Bank Stadium | E18: Green Bay Packers | F18: @ | G18: Minnesota Vikings | H18: -1.5 | I18: 46.5 | O18: =IF(OR(COUNTA(K18:L18)=2,COUNTA(M18:N18)=2,AND(ISBLANK(B18),COUNTA(K18:N18)>0),AND(H18="OFF",COUNTA(K18:L18)>0),AND(I18="OFF",COUNTA(M18:N18)>0)),"Error!","") | P18: 763.458.1631
B19: Sun, 3:25pm; FOX | D19: Lincoln Financial Field | E19: Washington Commanders | F19: @ | G19: Philadelphia Eagles | H19: -4.5 | I19: 44.5 | O19: =IF(OR(COUNTA(K19:L19)=2,COUNTA(M19:N19)=2,AND(ISBLANK(B19),COUNTA(K19:N19)>0),AND(H19="OFF",COUNTA(K19:L19)>0),AND(I19="OFF",COUNTA(M19:N19)>0)),"Error!","")
B20: Sun, 3:25pm; CBS | D20: SoFi Stadium | E20: Arizona Cardinals | F20: @ | G20: Los Angeles Chargers | H20: -10 | I20: 47.5 | O20: =IF(OR(COUNTA(K20:L20)=2,COUNTA(M20:N20)=2,AND(ISBLANK(B20),COUNTA(K20:N20)>0),AND(H20="OFF",COUNTA(K20:L20)>0),AND(I20="OFF",COUNTA(M20:N20)>0)),"Error!","")
B21: Sun, 7:20pm; *NBC | D21: MetLife Stadium | E21: Dallas Cowboys | F21: @ | G21: New York Giants | H21: 3 | I21: 48.5 | O21: =IF(OR(COUNTA(K21:L21)=2,COUNTA(M21:N21)=2,AND(ISBLANK(B21),COUNTA(K21:N21)>0),AND(H21="OFF",COUNTA(K21:L21)>0),AND(I21="OFF",COUNTA(M21:N21)>0)),"Error!","")
B22: Mon, 7:15pm; *ABC | D22: GEHA Field at Arrowhead Stadium | E22: Denver Broncos | F22: @ | G22: Kansas City Chiefs | H22: -3 | I22: 42.5 | O22: =IF(OR(COUNTA(K22:L22)=2,COUNTA(M22:N22)=2,AND(ISBLANK(B22),COUNTA(K22:N22)>0),AND(H22="OFF",COUNTA(K22:L22)>0),AND(I22="OFF",COUNTA(M22:N22)>0)),"Error!","")
C24: =IF(B25="","","You win if…") | G24: =IF(B25="","","You push if…")
B25: =IF(ISERROR(calcs!J65),"",calcs!I65) | C25: =IF(ISERROR(calcs!J65),"",calcs!J65) | G25: =IF(ISERROR(calcs!J65),"",calcs!K65)
B26: =IF(ISERROR(calcs!J66),"",calcs!I66) | C26: =IF(ISERROR(calcs!J66),"",calcs!J66) | G26: =IF(ISERROR(calcs!J66),"",calcs!K66)
B27: =IF(ISERROR(calcs!J67),"",calcs!I67) | C27: =IF(ISERROR(calcs!J67),"",calcs!J67) | G27: =IF(ISERROR(calcs!J67),"",calcs!K67)
B28: =IF(ISERROR(calcs!J68),"",calcs!I68) | C28: =IF(ISERROR(calcs!J68),"",calcs!J68) | G28: =IF(ISERROR(calcs!J68),"",calcs!K68)
B29: =IF(ISERROR(calcs!J69),"",calcs!I69) | C29: =IF(ISERROR(calcs!J69),"",calcs!J69) | G29: =IF(ISERROR(calcs!J69),"",calcs!K69)
B30: =IF(ISERROR(calcs!J70),"",calcs!I70) | C30: =IF(ISERROR(calcs!J70),"",calcs!J70) | G30: =IF(ISERROR(calcs!J70),"",calcs!K70)

Sheet calcs
A1: =G65&G66&G67&G68&G69&G70&G71&G72&G73&G74&G75&G76&G77&G78&G79&G80&G81&G82&G83&G84&G85&G86&G87&G88&G89&G90&G91&G92&G93&G94&G95&G96&G97&G98&G99&G100&G101&G102&G103&G104&G105&G106&G107&G108&G109&G110&G111&G112&G113&G114&G115&G116&G117&G118&G119&G120&G121&G122&G123&G124&G125&G126&G127&G128 | D1: Impossible Line: | E1: =Sheet1!K1 -> Michigan can win a game in regular time, not make-believe time…
B3: Away Win | C3: Home Win | D3: Line Push | E3: Under Win | F3: Over Win | G3: O / U Push | I3: =B3 -> Away Win | J3: =C3 -> Home Win | K3: =D3 -> Line Push | L3: =E3 -> Under Win | M3: =F3 -> Over Win | N3: =G3 -> O / U Push | P3: =I3 -> Away Win | Q3: =J3 -> Home Win | R3: =K3 -> Line Push | S3: =L3 -> Under Win | T3: =M3 -> Over Win | U3: =N3 -> O / U Push | W3: =P3 -> Away Win | X3: =Q3 -> Home Win | Y3: =R3 -> Line Push | Z3: =S3 -> Under Win | AA3: =T3 -> Over Win | AB3: =U3 -> O / U Push | AD3: =W3 -> Away Win | AE3: =X3 -> Home Win | AF3: =Y3 -> Line Push | AG3: =Z3 -> Under Win | AH3: =AA3 -> Over Win | AI3: =AB3 -> O / U Push
B4: 2 | C4: 3 | D4: 4 | E4: 2 | F4: 3 | G4: 4 | I4: Insert Away Team Name | P4: New Line | W4: Insert Home Team Name | AD4: Final Description
B5: =VLOOKUP(Sheet1!$H7,line_desc!$A:$D,B$4,0) -> Away win, tie, or Home win by 3 or less | C5: =VLOOKUP(Sheet1!$H7,line_desc!$A:$D,C$4,0) -> Home win by 4 or more | D5: =VLOOKUP(Sheet1!$H7,line_desc!$A:$D,D$4,0) -> Michigan can win a game in regular time, not make-believe time… | E5: =VLOOKUP(Sheet1!$I7,o_u_desc!$A:$D,E$4,0) -> Away + Home score is 44 or less | F5: =VLOOKUP(Sheet1!$I7,o_u_desc!$A:$D,F$4,0) -> Away + Home score is 45 or more | G5: =VLOOKUP(Sheet1!$I7,o_u_desc!$A:$D,G$4,0) -> Michigan can win a game in regular time, not make-believe time… | I5: =REPLACE(B5,SEARCH("Away",B5),4,Sheet1!$E7) -> New England Patriots win, tie, or Home win by 3 or less | J5: =REPLACE(C5,SEARCH("Away",C5),4,Sheet1!$E7) -> #VALUE! | K5: =REPLACE(D5,SEARCH("Away",D5),4,Sheet1!$E7) -> #VALUE! | L5: =REPLACE(E5,SEARCH("Away",E5),4,Sheet1!$E7) -> New England Patriots + Home score is 44 or less | M5: =REPLACE(F5,SEARCH("Away",F5),4,Sheet1!$E7) -> New England Patriots + Home score is 45 or more | N5: =REPLACE(G5,SEARCH("Away",G5),4,Sheet1!$E7) -> #VALUE! | P5: =IF(ISERROR(I5),B5,I5) -> New England Patriots win, tie, or Home win by 3 or less | Q5: =IF(ISERROR(J5),C5,J5) -> Home win by 4 or more | R5: =IF(ISERROR(K5),D5,K5) -> Michigan can win a game in regular time, not make-believe time… | S5: =IF(ISERROR(L5),E5,L5) -> New England Patriots + Home score is 44 or less | T5: =IF(ISERROR(M5),F5,M5) -> New England Patriots + Home score is 45 or more | U5: =IF(ISERROR(N5),G5,N5) -> Michigan can win a game in regular time, not make-believe time… | W5: =REPLACE(P5,SEARCH("Home",P5),4,Sheet1!$G7) -> New England Patriots win, tie, or Seattle Seahawks win by 3 or less | X5: =REPLACE(Q5,SEARCH("Home",Q5),4,Sheet1!$G7) -> Seattle Seahawks win by 4 or more | Y5: =REPLACE(R5,SEARCH("Home",R5),4,Sheet1!$G7) -> #VALUE! | Z5: =REPLACE(S5,SEARCH("Home",S5),4,Sheet1!$G7) -> New England Patriots + Seattle Seahawks score is 44 or less | AA5: =REPLACE(T5,SEARCH("Home",T5),4,Sheet1!$G7) -> New England Patriots + Seattle Seahawks score is 45 or more | AB5: =REPLACE(U5,SEARCH("Home",U5),4,Sheet1!$G7) -> #VALUE! | AD5: =IF(ISERROR(W5),P5,W5) -> New England Patriots win, tie, or Seattle Seahawks win by 3 or less | AE5: =IF(ISERROR(X5),Q5,X5) -> Seattle Seahawks win by 4 or more | AF5: =IF(ISERROR(Y5),R5,Y5) -> Michigan can win a game in regular time, not make-believe time… | AG5: =IF(ISERROR(Z5),S5,Z5) -> New England Patriots + Seattle Seahawks score is 44 or less | AH5: =IF(ISERROR(AA5),T5,AA5) -> New England Patriots + Seattle Seahawks score is 45 or more | AI5: =IF(ISERROR(AB5),U5,AB5) -> Michigan can win a game in regular time, not make-believe time…
B6: =VLOOKUP(Sheet1!$H8,line_desc!$A:$D,B$4,0) -> Away win, tie, or Home win by 3 or less | C6: =VLOOKUP(Sheet1!$H8,line_desc!$A:$D,C$4,0) -> Home win by 4 or more | D6: =VLOOKUP(Sheet1!$H8,line_desc!$A:$D,D$4,0) -> Michigan can win a game in regular time, not make-believe time… | E6: =VLOOKUP(Sheet1!$I8,o_u_desc!$A:$D,E$4,0) -> Away + Home score is 48 or less | F6: =VLOOKUP(Sheet1!$I8,o_u_desc!$A:$D,F$4,0) -> Away + Home score is 49 or more | G6: =VLOOKUP(Sheet1!$I8,o_u_desc!$A:$D,G$4,0) -> Michigan can win a game in regular time, not make-believe time… | I6: =REPLACE(B6,SEARCH("Away",B6),4,Sheet1!$E8) -> San Francisco 49ers win, tie, or Home win by 3 or less | J6: =REPLACE(C6,SEARCH("Away",C6),4,Sheet1!$E8) -> #VALUE! | K6: =REPLACE(D6,SEARCH("Away",D6),4,Sheet1!$E8) -> #VALUE! | L6: =REPLACE(E6,SEARCH("Away",E6),4,Sheet1!$E8) -> San Francisco 49ers + Home score is 48 or less | M6: =REPLACE(F6,SEARCH("Away",F6),4,Sheet1!$E8) -> San Francisco 49ers + Home score is 49 or more | N6: =REPLACE(G6,SEARCH("Away",G6),4,Sheet1!$E8) -> #VALUE! | P6: =IF(ISERROR(I6),B6,I6) -> San Francisco 49ers win, tie, or Home win by 3 or less | Q6: =IF(ISERROR(J6),C6,J6) -> Home win by 4 or more | R6: =IF(ISERROR(K6),D6,K6) -> Michigan can win a game in regular time, not make-believe time… | S6: =IF(ISERROR(L6),E6,L6) -> San Francisco 49ers + Home score is 48 or less | T6: =IF(ISERROR(M6),F6,M6) -> San Francisco 49ers + Home score is 49 or more | U6: =IF(ISERROR(N6),G6,N6) -> Michigan can win a game in regular time, not make-believe time… | W6: =REPLACE(P6,SEARCH("Home",P6),4,Sheet1!$G8) -> San Francisco 49ers win, tie, or Los Angeles Rams win by 3 or less | X6: =REPLACE(Q6,SEARCH("Home",Q6),4,Sheet1!$G8) -> Los Angeles Rams win by 4 or more | Y6: =REPLACE(R6,SEARCH("Home",R6),4,Sheet1!$G8) -> #VALUE! | Z6: =REPLACE(S6,SEARCH("Home",S6),4,Sheet1!$G8) -> San Francisco 49ers + Los Angeles Rams score is 48 or less | AA6: =REPLACE(T6,SEARCH("Home",T6),4,Sheet1!$G8) -> San Francisco 49ers + Los Angeles Rams score is 49 or more | AB6: =REPLACE(U6,SEARCH("Home",U6),4,Sheet1!$G8) -> #VALUE! | AD6: =IF(ISERROR(W6),P6,W6) -> San Francisco 49ers win, tie, or Los Angeles Rams win by 3 or less | AE6: =IF(ISERROR(X6),Q6,X6) -> Los Angeles Rams win by 4 or more | AF6: =IF(ISERROR(Y6),R6,Y6) -> Michigan can win a game in regular time, not make-believe time… | AG6: =IF(ISERROR(Z6),S6,Z6) -> San Francisco 49ers + Los Angeles Rams score is 48 or less | AH6: =IF(ISERROR(AA6),T6,AA6) -> San Francisco 49ers + Los Angeles Rams score is 49 or more | AI6: =IF(ISERROR(AB6),U6,AB6) -> Michigan can win a game in regular time, not make-believe time…
B7: =VLOOKUP(Sheet1!$H9,line_desc!$A:$D,B$4,0) -> Away win, tie, or Home win by 3 or less | C7: =VLOOKUP(Sheet1!$H9,line_desc!$A:$D,C$4,0) -> Home win by 4 or more | D7: =VLOOKUP(Sheet1!$H9,line_desc!$A:$D,D$4,0) -> Michigan can win a game in regular time, not make-believe time… | E7: =VLOOKUP(Sheet1!$I9,o_u_desc!$A:$D,E$4,0) -> Away + Home score is 50 or less | F7: =VLOOKUP(Sheet1!$I9,o_u_desc!$A:$D,F$4,0) -> Away + Home score is 51 or more | G7: =VLOOKUP(Sheet1!$I9,o_u_desc!$A:$D,G$4,0) -> Michigan can win a game in regular time, not make-believe time… | I7: =REPLACE(B7,SEARCH("Away",B7),4,Sheet1!$E9) -> Tampa Bay Buccaneers win, tie, or Home win by 3 or less | J7: =REPLACE(C7,SEARCH("Away",C7),4,Sheet1!$E9) -> #VALUE! | K7: =REPLACE(D7,SEARCH("Away",D7),4,Sheet1!$E9) -> #VALUE! | L7: =REPLACE(E7,SEARCH("Away",E7),4,Sheet1!$E9) -> Tampa Bay Buccaneers + Home score is 50 or less | M7: =REPLACE(F7,SEARCH("Away",F7),4,Sheet1!$E9) -> Tampa Bay Buccaneers + Home score is 51 or more | N7: =REPLACE(G7,SEARCH("Away",G7),4,Sheet1!$E9) -> #VALUE! | P7: =IF(ISERROR(I7),B7,I7) -> Tampa Bay Buccaneers win, tie, or Home win by 3 or less | Q7: =IF(ISERROR(J7),C7,J7) -> Home win by 4 or more | R7: =IF(ISERROR(K7),D7,K7) -> Michigan can win a game in regular time, not make-believe time… | S7: =IF(ISERROR(L7),E7,L7) -> Tampa Bay Buccaneers + Home score is 50 or less | T7: =IF(ISERROR(M7),F7,M7) -> Tampa Bay Buccaneers + Home score is 51 or more | U7: =IF(ISERROR(N7),G7,N7) -> Michigan can win a game in regular time, not make-believe time… | W7: =REPLACE(P7,SEARCH("Home",P7),4,Sheet1!$G9) -> Tampa Bay Buccaneers win, tie, or Cincinnati Bengals win by 3 or less | X7: =REPLACE(Q7,SEARCH("Home",Q7),4,Sheet1!$G9) -> Cincinnati Bengals win by 4 or more | Y7: =REPLACE(R7,SEARCH("Home",R7),4,Sheet1!$G9) -> #VALUE! | Z7: =REPLACE(S7,SEARCH("Home",S7),4,Sheet1!$G9) -> Tampa Bay Buccaneers + Cincinnati Bengals score is 50 or less | AA7: =REPLACE(T7,SEARCH("Home",T7),4,Sheet1!$G9) -> Tampa Bay Buccaneers + Cincinnati Bengals score is 51 or more | AB7: =REPLACE(U7,SEARCH("Home",U7),4,Sheet1!$G9) -> #VALUE! | AD7: =IF(ISERROR(W7),P7,W7) -> Tampa Bay Buccaneers win, tie, or Cincinnati Bengals win by 3 or less | AE7: =IF(ISERROR(X7),Q7,X7) -> Cincinnati Bengals win by 4 or more | AF7: =IF(ISERROR(Y7),R7,Y7) -> Michigan can win a game in regular time, not make-believe time… | AG7: =IF(ISERROR(Z7),S7,Z7) -> Tampa Bay Buccaneers + Cincinnati Bengals score is 50 or less | AH7: =IF(ISERROR(AA7),T7,AA7) -> Tampa Bay Buccaneers + Cincinnati Bengals score is 51 or more | AI7: =IF(ISERROR(AB7),U7,AB7) -> Michigan can win a game in regular time, not make-believe time…
B8: =VLOOKUP(Sheet1!$H10,line_desc!$A:$D,B$4,0) -> Away win, tie, or Home win by 6 or less | C8: =VLOOKUP(Sheet1!$H10,line_desc!$A:$D,C$4,0) -> Home win by 8 or more | D8: =VLOOKUP(Sheet1!$H10,line_desc!$A:$D,D$4,0) -> Home win by 7 | E8: =VLOOKUP(Sheet1!$I10,o_u_desc!$A:$D,E$4,0) -> Away + Home score is 49 or less | F8: =VLOOKUP(Sheet1!$I10,o_u_desc!$A:$D,F$4,0) -> Away + Home score is 50 or more | G8: =VLOOKUP(Sheet1!$I10,o_u_desc!$A:$D,G$4,0) -> Michigan can win a game in regular time, not make-believe time… | I8: =REPLACE(B8,SEARCH("Away",B8),4,Sheet1!$E10) -> New Orleans Saints win, tie, or Home win by 6 or less | J8: =REPLACE(C8,SEARCH("Away",C8),4,Sheet1!$E10) -> #VALUE! | K8: =REPLACE(D8,SEARCH("Away",D8),4,Sheet1!$E10) -> #VALUE! | L8: =REPLACE(E8,SEARCH("Away",E8),4,Sheet1!$E10) -> New Orleans Saints + Home score is 49 or less | M8: =REPLACE(F8,SEARCH("Away",F8),4,Sheet1!$E10) -> New Orleans Saints + Home score is 50 or more | N8: =REPLACE(G8,SEARCH("Away",G8),4,Sheet1!$E10) -> #VALUE! | P8: =IF(ISERROR(I8),B8,I8) -> New Orleans Saints win, tie, or Home win by 6 or less | Q8: =IF(ISERROR(J8),C8,J8) -> Home win by 8 or more | R8: =IF(ISERROR(K8),D8,K8) -> Home win by 7 | S8: =IF(ISERROR(L8),E8,L8) -> New Orleans Saints + Home score is 49 or less | T8: =IF(ISERROR(M8),F8,M8) -> New Orleans Saints + Home score is 50 or more | U8: =IF(ISERROR(N8),G8,N8) -> Michigan can win a game in regular time, not make-believe time… | W8: =REPLACE(P8,SEARCH("Home",P8),4,Sheet1!$G10) -> New Orleans Saints win, tie, or Detroit Lions win by 6 or less | X8: =REPLACE(Q8,SEARCH("Home",Q8),4,Sheet1!$G10) -> Detroit Lions win by 8 or more | Y8: =REPLACE(R8,SEARCH("Home",R8),4,Sheet1!$G10) -> Detroit Lions win by 7 | Z8: =REPLACE(S8,SEARCH("Home",S8),4,Sheet1!$G10) -> New Orleans Saints + Detroit Lions score is 49 or less | AA8: =REPLACE(T8,SEARCH("Home",T8),4,Sheet1!$G10) -> New Orleans Saints + Detroit Lions score is 50 or more | AB8: =REPLACE(U8,SEARCH("Home",U8),4,Sheet1!$G10) -> #VALUE! | AD8: =IF(ISERROR(W8),P8,W8) -> New Orleans Saints win, tie, or Detroit Lions win by 6 or less | AE8: =IF(ISERROR(X8),Q8,X8) -> Detroit Lions win by 8 or more | AF8: =IF(ISERROR(Y8),R8,Y8) -> Detroit Lions win by 7 | AG8: =IF(ISERROR(Z8),S8,Z8) -> New Orleans Saints + Detroit Lions score is 49 or less | AH8: =IF(ISERROR(AA8),T8,AA8) -> New Orleans Saints + Detroit Lions score is 50 or more | AI8: =IF(ISERROR(AB8),U8,AB8) -> Michigan can win a game in regular time, not make-believe time…
B9: =VLOOKUP(Sheet1!$H11,line_desc!$A:$D,B$4,0) -> Away win, tie, or Home win by 1 | C9: =VLOOKUP(Sheet1!$H11,line_desc!$A:$D,C$4,0) -> Home win by 2 or more | D9: =VLOOKUP(Sheet1!$H11,line_desc!$A:$D,D$4,0) -> Michigan can win a game in regular time, not make-believe time… | E9: =VLOOKUP(Sheet1!$I11,o_u_desc!$A:$D,E$4,0) -> Away + Home score is 39 or less | F9: =VLOOKUP(Sheet1!$I11,o_u_desc!$A:$D,F$4,0) -> Away + Home score is 40 or more | G9: =VLOOKUP(Sheet1!$I11,o_u_desc!$A:$D,G$4,0) -> Michigan can win a game in regular time, not make-believe time… | I9: =REPLACE(B9,SEARCH("Away",B9),4,Sheet1!$E11) -> New York Jets win, tie, or Home win by 1 | J9: =REPLACE(C9,SEARCH("Away",C9),4,Sheet1!$E11) -> #VALUE! | K9: =REPLACE(D9,SEARCH("Away",D9),4,Sheet1!$E11) -> #VALUE! | L9: =REPLACE(E9,SEARCH("Away",E9),4,Sheet1!$E11) -> New York Jets + Home score is 39 or less | M9: =REPLACE(F9,SEARCH("Away",F9),4,Sheet1!$E11) -> New York Jets + Home score is 40 or more | N9: =REPLACE(G9,SEARCH("Away",G9),4,Sheet1!$E11) -> #VALUE! | P9: =IF(ISERROR(I9),B9,I9) -> New York Jets win, tie, or Home win by 1 | Q9: =IF(ISERROR(J9),C9,J9) -> Home win by 2 or more | R9: =IF(ISERROR(K9),D9,K9) -> Michigan can win a game in regular time, not make-believe time… | S9: =IF(ISERROR(L9),E9,L9) -> New York Jets + Home score is 39 or less | T9: =IF(ISERROR(M9),F9,M9) -> New York Jets + Home score is 40 or more | U9: =IF(ISERROR(N9),G9,N9) -> Michigan can win a game in regular time, not make-believe time… | W9: =REPLACE(P9,SEARCH("Home",P9),4,Sheet1!$G11) -> New York Jets win, tie, or Tennessee Titans win by 1 | X9: =REPLACE(Q9,SEARCH("Home",Q9),4,Sheet1!$G11) -> Tennessee Titans win by 2 or more | Y9: =REPLACE(R9,SEARCH("Home",R9),4,Sheet1!$G11) -> #VALUE! | Z9: =REPLACE(S9,SEARCH("Home",S9),4,Sheet1!$G11) -> New York Jets + Tennessee Titans score is 39 or less | AA9: =REPLACE(T9,SEARCH("Home",T9),4,Sheet1!$G11) -> New York Jets + Tennessee Titans score is 40 or more | AB9: =REPLACE(U9,SEARCH("Home",U9),4,Sheet1!$G11) -> #VALUE! | AD9: =IF(ISERROR(W9),P9,W9) -> New York Jets win, tie, or Tennessee Titans win by 1 | AE9: =IF(ISERROR(X9),Q9,X9) -> Tennessee Titans win by 2 or more | AF9: =IF(ISERROR(Y9),R9,Y9) -> Michigan can win a game in regular time, not make-believe time… | AG9: =IF(ISERROR(Z9),S9,Z9) -> New York Jets + Tennessee Titans score is 39 or less | AH9: =IF(ISERROR(AA9),T9,AA9) -> New York Jets + Tennessee Titans score is 40 or more | AI9: =IF(ISERROR(AB9),U9,AB9) -> Michigan can win a game in regular time, not make-believe time…
B10: =VLOOKUP(Sheet1!$H12,line_desc!$A:$D,B$4,0) -> Away win by 4 or more | C10: =VLOOKUP(Sheet1!$H12,line_desc!$A:$D,C$4,0) -> Home win, tie, or Away win by 2 or less | D10: =VLOOKUP(Sheet1!$H12,line_desc!$A:$D,D$4,0) -> Away win by 3 | E10: =VLOOKUP(Sheet1!$I12,o_u_desc!$A:$D,E$4,0) -> Away + Home score is 47 or less | F10: =VLOOKUP(Sheet1!$I12,o_u_desc!$A:$D,F$4,0) -> Away + Home score is 48 or more | G10: =VLOOKUP(Sheet1!$I12,o_u_desc!$A:$D,G$4,0) -> Michigan can win a game in regular time, not make-believe time… | I10: =REPLACE(B10,SEARCH("Away",B10),4,Sheet1!$E12) -> Baltimore Ravens win by 4 or more | J10: =REPLACE(C10,SEARCH("Away",C10),4,Sheet1!$E12) -> Home win, tie, or Baltimore Ravens win by 2 or less | K10: =REPLACE(D10,SEARCH("Away",D10),4,Sheet1!$E12) -> Baltimore Ravens win by 3 | L10: =REPLACE(E10,SEARCH("Away",E10),4,Sheet1!$E12) -> Baltimore Ravens + Home score is 47 or less | M10: =REPLACE(F10,SEARCH("Away",F10),4,Sheet1!$E12) -> Baltimore Ravens + Home score is 48 or more | N10: =REPLACE(G10,SEARCH("Away",G10),4,Sheet1!$E12) -> #VALUE! | P10: =IF(ISERROR(I10),B10,I10) -> Baltimore Ravens win by 4 or more | Q10: =IF(ISERROR(J10),C10,J10) -> Home win, tie, or Baltimore Ravens win by 2 or less | R10: =IF(ISERROR(K10),D10,K10) -> Baltimore Ravens win by 3 | S10: =IF(ISERROR(L10),E10,L10) -> Baltimore Ravens + Home score is 47 or less | T10: =IF(ISERROR(M10),F10,M10) -> Baltimore Ravens + Home score is 48 or more | U10: =IF(ISERROR(N10),G10,N10) -> Michigan can win a game in regular time, not make-believe time… | W10: =REPLACE(P10,SEARCH("Home",P10),4,Sheet1!$G12) -> #VALUE! | X10: =REPLACE(Q10,SEARCH("Home",Q10),4,Sheet1!$G12) -> Indianapolis Colts win, tie, or Baltimore Ravens win by 2 or less | Y10: =REPLACE(R10,SEARCH("Home",R10),4,Sheet1!$G12) -> #VALUE! | Z10: =REPLACE(S10,SEARCH("Home",S10),4,Sheet1!$G12) -> Baltimore Ravens + Indianapolis Colts score is 47 or less | AA10: =REPLACE(T10,SEARCH("Home",T10),4,Sheet1!$G12) -> Baltimore Ravens + Indianapolis Colts score is 48 or more | AB10: =REPLACE(U10,SEARCH("Home",U10),4,Sheet1!$G12) -> #VALUE! | AD10: =IF(ISERROR(W10),P10,W10) -> Baltimore Ravens win by 4 or more | AE10: =IF(ISERROR(X10),Q10,X10) -> Indianapolis Colts win, tie, or Baltimore Ravens win by 2 or less | AF10: =IF(ISERROR(Y10),R10,Y10) -> Baltimore Ravens win by 3 | AG10: =IF(ISERROR(Z10),S10,Z10) -> Baltimore Ravens + Indianapolis Colts score is 47 or less | AH10: =IF(ISERROR(AA10),T10,AA10) -> Baltimore Ravens + Indianapolis Colts score is 48 or more | AI10: =IF(ISERROR(AB10),U10,AB10) -> Michigan can win a game in regular time, not make-believe time…
B11: =VLOOKUP(Sheet1!$H13,line_desc!$A:$D,B$4,0) -> Away win, tie, or Home win by 3 or less | C11: =VLOOKUP(Sheet1!$H13,line_desc!$A:$D,C$4,0) -> Home win by 4 or more | D11: =VLOOKUP(Sheet1!$H13,line_desc!$A:$D,D$4,0) -> Michigan can win a game in regular time, not make-believe time… | E11: =VLOOKUP(Sheet1!$I13,o_u_desc!$A:$D,E$4,0) -> Away + Home score is 42 or less | F11: =VLOOKUP(Sheet1!$I13,o_u_desc!$A:$D,F$4,0) -> Away + Home score is 43 or more | G11: =VLOOKUP(Sheet1!$I13,o_u_desc!$A:$D,G$4,0) -> Michigan can win a game in regular time, not make-believe time… | I11: =REPLACE(B11,SEARCH("Away",B11),4,Sheet1!$E13) -> Atlanta Falcons win, tie, or Home win by 3 or less | J11: =REPLACE(C11,SEARCH("Away",C11),4,Sheet1!$E13) -> #VALUE! | K11: =REPLACE(D11,SEARCH("Away",D11),4,Sheet1!$E13) -> #VALUE! | L11: =REPLACE(E11,SEARCH("Away",E11),4,Sheet1!$E13) -> Atlanta Falcons + Home score is 42 or less | M11: =REPLACE(F11,SEARCH("Away",F11),4,Sheet1!$E13) -> Atlanta Falcons + Home score is 43 or more | N11: =REPLACE(G11,SEARCH("Away",G11),4,Sheet1!$E13) -> #VALUE! | P11: =IF(ISERROR(I11),B11,I11) -> Atlanta Falcons win, tie, or Home win by 3 or less | Q11: =IF(ISERROR(J11),C11,J11) -> Home win by 4 or more | R11: =IF(ISERROR(K11),D11,K11) -> Michigan can win a game in regular time, not make-believe time… | S11: =IF(ISERROR(L11),E11,L11) -> Atlanta Falcons + Home score is 42 or less | T11: =IF(ISERROR(M11),F11,M11) -> Atlanta Falcons + Home score is 43 or more | U11: =IF(ISERROR(N11),G11,N11) -> Michigan can win a game in regular time, not make-believe time… | W11: =REPLACE(P11,SEARCH("Home",P11),4,Sheet1!$G13) -> Atlanta Falcons win, tie, or Pittsburgh Steelers win by 3 or less | X11: =REPLACE(Q11,SEARCH("Home",Q11),4,Sheet1!$G13) -> Pittsburgh Steelers win by 4 or more | Y11: =REPLACE(R11,SEARCH("Home",R11),4,Sheet1!$G13) -> #VALUE! | Z11: =REPLACE(S11,SEARCH("Home",S11),4,Sheet1!$G13) -> Atlanta Falcons + Pittsburgh Steelers score is 42 or less | AA11: =REPLACE(T11,SEARCH("Home",T11),4,Sheet1!$G13) -> Atlanta Falcons + Pittsburgh Steelers score is 43 or more | AB11: =REPLACE(U11,SEARCH("Home",U11),4,Sheet1!$G13) -> #VALUE! | AD11: =IF(ISERROR(W11),P11,W11) -> Atlanta Falcons win, tie, or Pittsburgh Steelers win by 3 or less | AE11: =IF(ISERROR(X11),Q11,X11) -> Pittsburgh Steelers win by 4 or more | AF11: =IF(ISERROR(Y11),R11,Y11) -> Michigan can win a game in regular time, not make-believe time… | AG11: =IF(ISERROR(Z11),S11,Z11) -> Atlanta Falcons + Pittsburgh Steelers score is 42 or less | AH11: =IF(ISERROR(AA11),T11,AA11) -> Atlanta Falcons + Pittsburgh Steelers score is 43 or more | AI11: =IF(ISERROR(AB11),U11,AB11) -> Michigan can win a game in regular time, not make-believe time…
B12: =VLOOKUP(Sheet1!$H14,line_desc!$A:$D,B$4,0) -> Away win by 4 or more | C12: =VLOOKUP(Sheet1!$H14,line_desc!$A:$D,C$4,0) -> Home win, tie, or Away win by 2 or less | D12: =VLOOKUP(Sheet1!$H14,line_desc!$A:$D,D$4,0) -> Away win by 3 | E12: =VLOOKUP(Sheet1!$I14,o_u_desc!$A:$D,E$4,0) -> Away + Home score is 46 or less | F12: =VLOOKUP(Sheet1!$I14,o_u_desc!$A:$D,F$4,0) -> Away + Home score is 47 or more | G12: =VLOOKUP(Sheet1!$I14,o_u_desc!$A:$D,G$4,0) -> Michigan can win a game in regular time, not make-believe time… | I12: =REPLACE(B12,SEARCH("Away",B12),4,Sheet1!$E14) -> Chicago Bears win by 4 or more | J12: =REPLACE(C12,SEARCH("Away",C12),4,Sheet1!$E14) -> Home win, tie, or Chicago Bears win by 2 or less | K12: =REPLACE(D12,SEARCH("Away",D12),4,Sheet1!$E14) -> Chicago Bears win by 3 | L12: =REPLACE(E12,SEARCH("Away",E12),4,Sheet1!$E14) -> Chicago Bears + Home score is 46 or less | M12: =REPLACE(F12,SEARCH("Away",F12),4,Sheet1!$E14) -> Chicago Bears + Home score is 47 or more | N12: =REPLACE(G12,SEARCH("Away",G12),4,Sheet1!$E14) -> #VALUE! | P12: =IF(ISERROR(I12),B12,I12) -> Chicago Bears win by 4 or more | Q12: =IF(ISERROR(J12),C12,J12) -> Home win, tie, or Chicago Bears win by 2 or less | R12: =IF(ISERROR(K12),D12,K12) -> Chicago Bears win by 3 | S12: =IF(ISERROR(L12),E12,L12) -> Chicago Bears + Home score is 46 or less | T12: =IF(ISERROR(M12),F12,M12) -> Chicago Bears + Home score is 47 or more | U12: =IF(ISERROR(N12),G12,N12) -> Michigan can win a game in regular time, not make-believe time… | W12: =REPLACE(P12,SEARCH("Home",P12),4,Sheet1!$G14) -> #VALUE! | X12: =REPLACE(Q12,SEARCH("Home",Q12),4,Sheet1!$G14) -> Carolina Panthers win, tie, or Chicago Bears win by 2 or less | Y12: =REPLACE(R12,SEARCH("Home",R12),4,Sheet1!$G14) -> #VALUE! | Z12: =REPLACE(S12,SEARCH("Home",S12),4,Sheet1!$G14) -> Chicago Bears + Carolina Panthers score is 46 or less | AA12: =REPLACE(T12,SEARCH("Home",T12),4,Sheet1!$G14) -> Chicago Bears + Carolina Panthers score is 47 or more | AB12: =REPLACE(U12,SEARCH("Home",U12),4,Sheet1!$G14) -> #VALUE! | AD12: =IF(ISERROR(W12),P12,W12) -> Chicago Bears win by 4 or more | AE12: =IF(ISERROR(X12),Q12,X12) -> Carolina Panthers win, tie, or Chicago Bears win by 2 or less | AF12: =IF(ISERROR(Y12),R12,Y12) -> Chicago Bears win by 3 | AG12: =IF(ISERROR(Z12),S12,Z12) -> Chicago Bears + Carolina Panthers score is 46 or less | AH12: =IF(ISERROR(AA12),T12,AA12) -> Chicago Bears + Carolina Panthers score is 47 or more | AI12: =IF(ISERROR(AB12),U12,AB12) -> Michigan can win a game in regular time, not make-believe time…
B13: =VLOOKUP(Sheet1!$H15,line_desc!$A:$D,B$4,0) -> Away win, tie, or Home win by 7 or less | C13: =VLOOKUP(Sheet1!$H15,line_desc!$A:$D,C$4,0) -> Home win by 8 or more | D13: =VLOOKUP(Sheet1!$H15,line_desc!$A:$D,D$4,0) -> Michigan can win a game in regular time, not make-believe time… | E13: =VLOOKUP(Sheet1!$I15,o_u_desc!$A:$D,E$4,0) -> Away + Home score is 40 or less | F13: =VLOOKUP(Sheet1!$I15,o_u_desc!$A:$D,F$4,0) -> Away + Home score is 41 or more | G13: =VLOOKUP(Sheet1!$I15,o_u_desc!$A:$D,G$4,0) -> Michigan can win a game in regular time, not make-believe time… | I13: =REPLACE(B13,SEARCH("Away",B13),4,Sheet1!$E15) -> Cleveland Browns win, tie, or Home win by 7 or less | J13: =REPLACE(C13,SEARCH("Away",C13),4,Sheet1!$E15) -> #VALUE! | K13: =REPLACE(D13,SEARCH("Away",D13),4,Sheet1!$E15) -> #VALUE! | L13: =REPLACE(E13,SEARCH("Away",E13),4,Sheet1!$E15) -> Cleveland Browns + Home score is 40 or less | M13: =REPLACE(F13,SEARCH("Away",F13),4,Sheet1!$E15) -> Cleveland Browns + Home score is 41 or more | N13: =REPLACE(G13,SEARCH("Away",G13),4,Sheet1!$E15) -> #VALUE! | P13: =IF(ISERROR(I13),B13,I13) -> Cleveland Browns win, tie, or Home win by 7 or less | Q13: =IF(ISERROR(J13),C13,J13) -> Home win by 8 or more | R13: =IF(ISERROR(K13),D13,K13) -> Michigan can win a game in regular time, not make-believe time… | S13: =IF(ISERROR(L13),E13,L13) -> Cleveland Browns + Home score is 40 or less | T13: =IF(ISERROR(M13),F13,M13) -> Cleveland Browns + Home score is 41 or more | U13: =IF(ISERROR(N13),G13,N13) -> Michigan can win a game in regular time, not make-believe time… | W13: =REPLACE(P13,SEARCH("Home",P13),4,Sheet1!$G15) -> Cleveland Browns win, tie, or Jacksonville Jaguars win by 7 or less | X13: =REPLACE(Q13,SEARCH("Home",Q13),4,Sheet1!$G15) -> Jacksonville Jaguars win by 8 or more | Y13: =REPLACE(R13,SEARCH("Home",R13),4,Sheet1!$G15) -> #VALUE! | Z13: =REPLACE(S13,SEARCH("Home",S13),4,Sheet1!$G15) -> Cleveland Browns + Jacksonville Jaguars score is 40 or less | AA13: =REPLACE(T13,SEARCH("Home",T13),4,Sheet1!$G15) -> Cleveland Browns + Jacksonville Jaguars score is 41 or more | AB13: =REPLACE(U13,SEARCH("Home",U13),4,Sheet1!$G15) -> #VALUE! | AD13: =IF(ISERROR(W13),P13,W13) -> Cleveland Browns win, tie, or Jacksonville Jaguars win by 7 or less | AE13: =IF(ISERROR(X13),Q13,X13) -> Jacksonville Jaguars win by 8 or more | AF13: =IF(ISERROR(Y13),R13,Y13) -> Michigan can win a game in regular time, not make-believe time… | AG13: =IF(ISERROR(Z13),S13,Z13) -> Cleveland Browns + Jacksonville Jaguars score is 40 or less | AH13: =IF(ISERROR(AA13),T13,AA13) -> Cleveland Browns + Jacksonville Jaguars score is 41 or more | AI13: =IF(ISERROR(AB13),U13,AB13) -> Michigan can win a game in regular time, not make-believe time…
B14: =VLOOKUP(Sheet1!$H16,line_desc!$A:$D,B$4,0) -> Away win by 2 or more | C14: =VLOOKUP(Sheet1!$H16,line_desc!$A:$D,C$4,0) -> Home win, tie, or Away win by 1 | D14: =VLOOKUP(Sheet1!$H16,line_desc!$A:$D,D$4,0) -> Michigan can win a game in regular time, not make-believe time… | E14: =VLOOKUP(Sheet1!$I16,o_u_desc!$A:$D,E$4,0) -> Away + Home score is 44 or less | F14: =VLOOKUP(Sheet1!$I16,o_u_desc!$A:$D,F$4,0) -> Away + Home score is 45 or more | G14: =VLOOKUP(Sheet1!$I16,o_u_desc!$A:$D,G$4,0) -> Michigan can win a game in regular time, not make-believe time… | I14: =REPLACE(B14,SEARCH("Away",B14),4,Sheet1!$E16) -> Buffalo Bills win by 2 or more | J14: =REPLACE(C14,SEARCH("Away",C14),4,Sheet1!$E16) -> Home win, tie, or Buffalo Bills win by 1 | K14: =REPLACE(D14,SEARCH("Away",D14),4,Sheet1!$E16) -> #VALUE! | L14: =REPLACE(E14,SEARCH("Away",E14),4,Sheet1!$E16) -> Buffalo Bills + Home score is 44 or less | M14: =REPLACE(F14,SEARCH("Away",F14),4,Sheet1!$E16) -> Buffalo Bills + Home score is 45 or more | N14: =REPLACE(G14,SEARCH("Away",G14),4,Sheet1!$E16) -> #VALUE! | P14: =IF(ISERROR(I14),B14,I14) -> Buffalo Bills win by 2 or more | Q14: =IF(ISERROR(J14),C14,J14) -> Home win, tie, or Buffalo Bills win by 1 | R14: =IF(ISERROR(K14),D14,K14) -> Michigan can win a game in regular time, not make-believe time… | S14: =IF(ISERROR(L14),E14,L14) -> Buffalo Bills + Home score is 44 or less | T14: =IF(ISERROR(M14),F14,M14) -> Buffalo Bills + Home score is 45 or more | U14: =IF(ISERROR(N14),G14,N14) -> Michigan can win a game in regular time, not make-believe time… | W14: =REPLACE(P14,SEARCH("Home",P14),4,Sheet1!$G16) -> #VALUE! | X14: =REPLACE(Q14,SEARCH("Home",Q14),4,Sheet1!$G16) -> Houston Texans win, tie, or Buffalo Bills win by 1 | Y14: =REPLACE(R14,SEARCH("Home",R14),4,Sheet1!$G16) -> #VALUE! | Z14: =REPLACE(S14,SEARCH("Home",S14),4,Sheet1!$G16) -> Buffalo Bills + Houston Texans score is 44 or less | AA14: =REPLACE(T14,SEARCH("Home",T14),4,Sheet1!$G16) -> Buffalo Bills + Houston Texans score is 45 or more | AB14: =REPLACE(U14,SEARCH("Home",U14),4,Sheet1!$G16) -> #VALUE! | AD14: =IF(ISERROR(W14),P14,W14) -> Buffalo Bills win by 2 or more | AE14: =IF(ISERROR(X14),Q14,X14) -> Houston Texans win, tie, or Buffalo Bills win by 1 | AF14: =IF(ISERROR(Y14),R14,Y14) -> Michigan can win a game in regular time, not make-believe time… | AG14: =IF(ISERROR(Z14),S14,Z14) -> Buffalo Bills + Houston Texans score is 44 or less | AH14: =IF(ISERROR(AA14),T14,AA14) -> Buffalo Bills + Houston Texans score is 45 or more | AI14: =IF(ISERROR(AB14),U14,AB14) -> Michigan can win a game in regular time, not make-believe time…
B15: =VLOOKUP(Sheet1!$H17,line_desc!$A:$D,B$4,0) -> Away win, tie, or Home win by 3 or less | C15: =VLOOKUP(Sheet1!$H17,line_desc!$A:$D,C$4,0) -> Home win by 4 or more | D15: =VLOOKUP(Sheet1!$H17,line_desc!$A:$D,D$4,0) -> Michigan can win a game in regular time, not make-believe time… | E15: =VLOOKUP(Sheet1!$I17,o_u_desc!$A:$D,E$4,0) -> Away + Home score is 40 or less | F15: =VLOOKUP(Sheet1!$I17,o_u_desc!$A:$D,F$4,0) -> Away + Home score is 41 or more | G15: =VLOOKUP(Sheet1!$I17,o_u_desc!$A:$D,G$4,0) -> Michigan can win a game in regular time, not make-believe time… | I15: =REPLACE(B15,SEARCH("Away",B15),4,Sheet1!$E17) -> Miami Dolphins win, tie, or Home win by 3 or less | J15: =REPLACE(C15,SEARCH("Away",C15),4,Sheet1!$E17) -> #VALUE! | K15: =REPLACE(D15,SEARCH("Away",D15),4,Sheet1!$E17) -> #VALUE! | L15: =REPLACE(E15,SEARCH("Away",E15),4,Sheet1!$E17) -> Miami Dolphins + Home score is 40 or less | M15: =REPLACE(F15,SEARCH("Away",F15),4,Sheet1!$E17) -> Miami Dolphins + Home score is 41 or more | N15: =REPLACE(G15,SEARCH("Away",G15),4,Sheet1!$E17) -> #VALUE! | P15: =IF(ISERROR(I15),B15,I15) -> Miami Dolphins win, tie, or Home win by 3 or less | Q15: =IF(ISERROR(J15),C15,J15) -> Home win by 4 or more | R15: =IF(ISERROR(K15),D15,K15) -> Michigan can win a game in regular time, not make-believe time… | S15: =IF(ISERROR(L15),E15,L15) -> Miami Dolphins + Home score is 40 or less | T15: =IF(ISERROR(M15),F15,M15) -> Miami Dolphins + Home score is 41 or more | U15: =IF(ISERROR(N15),G15,N15) -> Michigan can win a game in regular time, not make-believe time… | W15: =REPLACE(P15,SEARCH("Home",P15),4,Sheet1!$G17) -> Miami Dolphins win, tie, or Las Vegas Raiders win by 3 or less | X15: =REPLACE(Q15,SEARCH("Home",Q15),4,Sheet1!$G17) -> Las Vegas Raiders win by 4 or more | Y15: =REPLACE(R15,SEARCH("Home",R15),4,Sheet1!$G17) -> #VALUE! | Z15: =REPLACE(S15,SEARCH("Home",S15),4,Sheet1!$G17) -> Miami Dolphins + Las Vegas Raiders score is 40 or less | AA15: =REPLACE(T15,SEARCH("Home",T15),4,Sheet1!$G17) -> Miami Dolphins + Las Vegas Raiders score is 41 or more | AB15: =REPLACE(U15,SEARCH("Home",U15),4,Sheet1!$G17) -> #VALUE! | AD15: =IF(ISERROR(W15),P15,W15) -> Miami Dolphins win, tie, or Las Vegas Raiders win by 3 or less | AE15: =IF(ISERROR(X15),Q15,X15) -> Las Vegas Raiders win by 4 or more | AF15: =IF(ISERROR(Y15),R15,Y15) -> Michigan can win a game in regular time, not make-believe time… | AG15: =IF(ISERROR(Z15),S15,Z15) -> Miami Dolphins + Las Vegas Raiders score is 40 or less | AH15: =IF(ISERROR(AA15),T15,AA15) -> Miami Dolphins + Las Vegas Raiders score is 41 or more | AI15: =IF(ISERROR(AB15),U15,AB15) -> Michigan can win a game in regular time, not make-believe time…
B16: =VLOOKUP(Sheet1!$H18,line_desc!$A:$D,B$4,0) -> Away win, tie, or Home win by 1 | C16: =VLOOKUP(Sheet1!$H18,line_desc!$A:$D,C$4,0) -> Home win by 2 or more | D16: =VLOOKUP(Sheet1!$H18,line_desc!$A:$D,D$4,0) -> Michigan can win a game in regular time, not make-believe time… | E16: =VLOOKUP(Sheet1!$I18,o_u_desc!$A:$D,E$4,0) -> Away + Home score is 46 or less | F16: =VLOOKUP(Sheet1!$I18,o_u_desc!$A:$D,F$4,0) -> Away + Home score is 47 or more | G16: =VLOOKUP(Sheet1!$I18,o_u_desc!$A:$D,G$4,0) -> Michigan can win a game in regular time, not make-believe time… | I16: =REPLACE(B16,SEARCH("Away",B16),4,Sheet1!$E18) -> Green Bay Packers win, tie, or Home win by 1 | J16: =REPLACE(C16,SEARCH("Away",C16),4,Sheet1!$E18) -> #VALUE! | K16: =REPLACE(D16,SEARCH("Away",D16),4,Sheet1!$E18) -> #VALUE! | L16: =REPLACE(E16,SEARCH("Away",E16),4,Sheet1!$E18) -> Green Bay Packers + Home score is 46 or less | M16: =REPLACE(F16,SEARCH("Away",F16),4,Sheet1!$E18) -> Green Bay Packers + Home score is 47 or more | N16: =REPLACE(G16,SEARCH("Away",G16),4,Sheet1!$E18) -> #VALUE! | P16: =IF(ISERROR(I16),B16,I16) -> Green Bay Packers win, tie, or Home win by 1 | Q16: =IF(ISERROR(J16),C16,J16) -> Home win by 2 or more | R16: =IF(ISERROR(K16),D16,K16) -> Michigan can win a game in regular time, not make-believe time… | S16: =IF(ISERROR(L16),E16,L16) -> Green Bay Packers + Home score is 46 or less | T16: =IF(ISERROR(M16),F16,M16) -> Green Bay Packers + Home score is 47 or more | U16: =IF(ISERROR(N16),G16,N16) -> Michigan can win a game in regular time, not make-believe time… | W16: =REPLACE(P16,SEARCH("Home",P16),4,Sheet1!$G18) -> Green Bay Packers win, tie, or Minnesota Vikings win by 1 | X16: =REPLACE(Q16,SEARCH("Home",Q16),4,Sheet1!$G18) -> Minnesota Vikings win by 2 or more | Y16: =REPLACE(R16,SEARCH("Home",R16),4,Sheet1!$G18) -> #VALUE! | Z16: =REPLACE(S16,SEARCH("Home",S16),4,Sheet1!$G18) -> Green Bay Packers + Minnesota Vikings score is 46 or less | AA16: =REPLACE(T16,SEARCH("Home",T16),4,Sheet1!$G18) -> Green Bay Packers + Minnesota Vikings score is 47 or more | AB16: =REPLACE(U16,SEARCH("Home",U16),4,Sheet1!$G18) -> #VALUE! | AD16: =IF(ISERROR(W16),P16,W16) -> Green Bay Packers win, tie, or Minnesota Vikings win by 1 | AE16: =IF(ISERROR(X16),Q16,X16) -> Minnesota Vikings win by 2 or more | AF16: =IF(ISERROR(Y16),R16,Y16) -> Michigan can win a game in regular time, not make-believe time… | AG16: =IF(ISERROR(Z16),S16,Z16) -> Green Bay Packers + Minnesota Vikings score is 46 or less | AH16: =IF(ISERROR(AA16),T16,AA16) -> Green Bay Packers + Minnesota Vikings score is 47 or more | AI16: =IF(ISERROR(AB16),U16,AB16) -> Michigan can win a game in regular time, not make-believe time…
... B20: =VLOOKUP(Sheet1!$H22,line_desc!$A:$D,B$4,0) -> Away win, tie, or Home win by 2 or less | C20: =VLOOKUP(Sheet1!$H22,line_desc!$A:$D,C$4,0) -> Home win by 4 or more | D20: =VLOOKUP(Sheet1!$H22,line_desc!$A:$D,D$4,0) -> Home win by 3 | E20: =VLOOKUP(Sheet1!$I22,o_u_desc!$A:$D,E$4,0) -> Away + Home score is 42 or less | F20: =VLOOKUP(Sheet1!$I22,o_u_desc!$A:$D,F$4,0) -> Away + Home score is 43 or more | G20: =VLOOKUP(Sheet1!$I22,o_u_desc!$A:$D,G$4,0) -> Michigan can win a game in regular time, not make-believe time… | I20: =REPLACE(B20,SEARCH("Away",B20),4,Sheet1!$E22) -> Denver Broncos win, tie, or Home win by 2 or less | J20: =REPLACE(C20,SEARCH("Away",C20),4,Sheet1!$E22) -> #VALUE! | K20: =REPLACE(D20,SEARCH("Away",D20),4,Sheet1!$E22) -> #VALUE! | L20: =REPLACE(E20,SEARCH("Away",E20),4,Sheet1!$E22) -> Denver Broncos + Home score is 42 or less | M20: =REPLACE(F20,SEARCH("Away",F20),4,Sheet1!$E22) -> Denver Broncos + Home score is 43 or more | N20: =REPLACE(G20,SEARCH("Away",G20),4,Sheet1!$E22) -> #VALUE! | P20: =IF(ISERROR(I20),B20,I20) -> Denver Broncos win, tie, or Home win by 2 or less | Q20: =IF(ISERROR(J20),C20,J20) -> Home win by 4 or more | R20: =IF(ISERROR(K20),D20,K20) -> Home win by 3 | S20: =IF(ISERROR(L20),E20,L20) -> Denver Broncos + Home score is 42 or less | T20: =IF(ISERROR(M20),F20,M20) -> Denver Broncos + Home score is 43 or more | U20: =IF(ISERROR(N20),G20,N20) -> Michigan can win a game in regular time, not make-believe time… | W20: =REPLACE(P20,SEARCH("Home",P20),4,Sheet1!$G22) -> Denver Broncos win, tie, or Kansas City Chiefs win by 2 or less | X20: =REPLACE(Q20,SEARCH("Home",Q20),4,Sheet1!$G22) -> Kansas City Chiefs win by 4 or more | Y20: =REPLACE(R20,SEARCH("Home",R20),4,Sheet1!$G22) -> Kansas City Chiefs win by 3 | Z20: =REPLACE(S20,SEARCH("Home",S20),4,Sheet1!$G22) -> Denver Broncos + Kansas City Chiefs score is 42 or less | AA20: =REPLACE(T20,SEARCH("Home",T20),4,Sheet1!$G22) -> Denver Broncos + Kansas City Chiefs score is 43 or more | AB20: =REPLACE(U20,SEARCH("Home",U20),4,Sheet1!$G22) -> #VALUE! | AD20: =IF(ISERROR(W20),P20,W20) -> Denver Broncos win, tie, or Kansas City Chiefs win by 2 or less | AE20: =IF(ISERROR(X20),Q20,X20) -> Kansas City Chiefs win by 4 or more | AF20: =IF(ISERROR(Y20),R20,Y20) -> Kansas City Chiefs win by 3 | AG20: =IF(ISERROR(Z20),S20,Z20) -> Denver Broncos + Kansas City Chiefs score is 42 or less | AH20: =IF(ISERROR(AA20),T20,AA20) -> Denver Broncos + Kansas City Chiefs score is 43 or more | AI20: =IF(ISERROR(AB20),U20,AB20) -> Michigan can win a game in regular time, not make-believe time…
B23: Win Table | G23: Push Table
B24: Away | C24: Home | D24: Under | E24: Over | G24: =B24 -> Away | H24: =C24 -> Home | I24: =D24 -> Under | J24: =E24 -> Over
B25: =AD5 -> New England Patriots win, tie, or Seattle Seahawks win by 3 or less | C25: =AE5 -> Seattle Seahawks win by 4 or more | D25: =AG5 -> New England Patriots + Seattle Seahawks score is 44 or less | E25: =AH5 -> New England Patriots + Seattle Seahawks score is 45 or more | G25: =AF5 -> Michigan can win a game in regular time, not make-believe time… | H25: =AF5 -> Michigan can win a game in regular time, not make-believe time… | I25: =AI5 -> Michigan can win a game in regular time, not make-believe time… | J25: =AI5 -> Michigan can win a game in regular time, not make-believe time…
B26: =AD6 -> San Francisco 49ers win, tie, or Los Angeles Rams win by 3 or less | C26: =AE6 -> Los Angeles Rams win by 4 or more | D26: =AG6 -> San Francisco 49ers + Los Angeles Rams score is 48 or less | E26: =AH6 -> San Francisco 49ers + Los Angeles Rams score is 49 or more | G26: =AF6 -> Michigan can win a game in regular time, not make-believe time… | H26: =AF6 -> Michigan can win a game in regular time, not make-believe time… | I26: =AI6 -> Michigan can win a game in regular time, not make-believe time… | J26: =AI6 -> Michigan can win a game in regular time, not make-believe time…
B27: =AD7 -> Tampa Bay Buccaneers win, tie, or Cincinnati Bengals win by 3 or less | C27: =AE7 -> Cincinnati Bengals win by 4 or more | D27: =AG7 -> Tampa Bay Buccaneers + Cincinnati Bengals score is 50 or less | E27: =AH7 -> Tampa Bay Buccaneers + Cincinnati Bengals score is 51 or more | G27: =AF7 -> Michigan can win a game in regular time, not make-believe time… | H27: =AF7 -> Michigan can win a game in regular time, not make-believe time… | I27: =AI7 -> Michigan can win a game in regular time, not make-believe time… | J27: =AI7 -> Michigan can win a game in regular time, not make-believe time…
B28: =AD8 -> New Orleans Saints win, tie, or Detroit Lions win by 6 or less | C28: =AE8 -> Detroit Lions win by 8 or more | D28: =AG8 -> New Orleans Saints + Detroit Lions score is 49 or less | E28: =AH8 -> New Orleans Saints + Detroit Lions score is 50 or more | G28: =AF8 -> Detroit Lions win by 7 | H28: =AF8 -> Detroit Lions win by 7 | I28: =AI8 -> Michigan can win a game in regular time, not make-believe time… | J28: =AI8 -> Michigan can win a game in regular time, not make-believe time…
B29: =AD9 -> New York Jets win, tie, or Tennessee Titans win by 1 | C29: =AE9 -> Tennessee Titans win by 2 or more | D29: =AG9 -> New York Jets + Tennessee Titans score is 39 or less | E29: =AH9 -> New York Jets + Tennessee Titans score is 40 or more | G29: =AF9 -> Michigan can win a game in regular time, not make-believe time… | H29: =AF9 -> Michigan can win a game in regular time, not make-believe time… | I29: =AI9 -> Michigan can win a game in regular time, not make-believe time… | J29: =AI9 -> Michigan can win a game in regular time, not make-believe time…
B30: =AD10 -> Baltimore Ravens win by 4 or more | C30: =AE10 -> Indianapolis Colts win, tie, or Baltimore Ravens win by 2 or less | D30: =AG10 -> Baltimore Ravens + Indianapolis Colts score is 47 or less | E30: =AH10 -> Baltimore Ravens + Indianapolis Colts score is 48 or more | G30: =AF10 -> Baltimore Ravens win by 3 | H30: =AF10 -> Baltimore Ravens win by 3 | I30: =AI10 -> Michigan can win a game in regular time, not make-believe time… | J30: =AI10 -> Michigan can win a game in regular time, not make-believe time…
B31: =AD11 -> Atlanta Falcons win, tie, or Pittsburgh Steelers win by 3 or less | C31: =AE11 -> Pittsburgh Steelers win by 4 or more | D31: =AG11 -> Atlanta Falcons + Pittsburgh Steelers score is 42 or less | E31: =AH11 -> Atlanta Falcons + Pittsburgh Steelers score is 43 or more | G31: =AF11 -> Michigan can win a game in regular time, not make-believe time… | H31: =AF11 -> Michigan can win a game in regular time, not make-believe time… | I31: =AI11 -> Michigan can win a game in regular time, not make-believe time… | J31: =AI11 -> Michigan can win a game in regular time, not make-believe time…
B32: =AD12 -> Chicago Bears win by 4 or more | C32: =AE12 -> Carolina Panthers win, tie, or Chicago Bears win by 2 or less | D32: =AG12 -> Chicago Bears + Carolina Panthers score is 46 or less | E32: =AH12 -> Chicago Bears + Carolina Panthers score is 47 or more | G32: =AF12 -> Chicago Bears win by 3 | H32: =AF12 -> Chicago Bears win by 3 | I32: =AI12 -> Michigan can win a game in regular time, not make-believe time… | J32: =AI12 -> Michigan can win a game in regular time, not make-believe time…
B33: =AD13 -> Cleveland Browns win, tie, or Jacksonville Jaguars win by 7 or less | C33: =AE13 -> Jacksonville Jaguars win by 8 or more | D33: =AG13 -> Cleveland Browns + Jacksonville Jaguars score is 40 or less | E33: =AH13 -> Cleveland Browns + Jacksonville Jaguars score is 41 or more | G33: =AF13 -> Michigan can win a game in regular time, not make-believe time… | H33: =AF13 -> Michigan can win a game in regular time, not make-believe time… | I33: =AI13 -> Michigan can win a game in regular time, not make-believe time… | J33: =AI13 -> Michigan can win a game in regular time, not make-believe time…
B34: =AD14 -> Buffalo Bills win by 2 or more | C34: =AE14 -> Houston Texans win, tie, or Buffalo Bills win by 1 | D34: =AG14 -> Buffalo Bills + Houston Texans score is 44 or less | E34: =AH14 -> Buffalo Bills + Houston Texans score is 45 or more | G34: =AF14 -> Michigan can win a game in regular time, not make-believe time… | H34: =AF14 -> Michigan can win a game in regular time, not make-believe time… | I34: =AI14 -> Michigan can win a game in regular time, not make-believe time… | J34: =AI14 -> Michigan can win a game in regular time, not make-believe time…
B35: =AD15 -> Miami Dolphins win, tie, or Las Vegas Raiders win by 3 or less | C35: =AE15 -> Las Vegas Raiders win by 4 or more | D35: =AG15 -> Miami Dolphins + Las Vegas Raiders score is 40 or less | E35: =AH15 -> Miami Dolphins + Las Vegas Raiders score is 41 or more | G35: =AF15 -> Michigan can win a game in regular time, not make-believe time… | H35: =AF15 -> Michigan can win a game in regular time, not make-believe time… | I35: =AI15 -> Michigan can win a game in regular time, not make-believe time… | J35: =AI15 -> Michigan can win a game in regular time, not make-believe time…
B36: =AD16 -> Green Bay Packers win, tie, or Minnesota Vikings win by 1 | C36: =AE16 -> Minnesota Vikings win by 2 or more | D36: =AG16 -> Green Bay Packers + Minnesota Vikings score is 46 or less | E36: =AH16 -> Green Bay Packers + Minnesota Vikings score is 47 or more | G36: =AF16 -> Michigan can win a game in regular time, not make-believe time… | H36: =AF16 -> Michigan can win a game in regular time, not make-believe time… | I36: =AI16 -> Michigan can win a game in regular time, not make-believe time… | J36: =AI16 -> Michigan can win a game in regular time, not make-believe time…
... B40: =AD20 -> Denver Broncos win, tie, or Kansas City Chiefs win by 2 or less | C40: =AE20 -> Kansas City Chiefs win by 4 or more | D40: =AG20 -> Denver Broncos + Kansas City Chiefs score is 42 or less | E40: =AH20 -> Denver Broncos + Kansas City Chiefs score is 43 or more | G40: =AF20 -> Kansas City Chiefs win by 3 | H40: =AF20 -> Kansas City Chiefs win by 3 | I40: =AI20 -> Michigan can win a game in regular time, not make-believe time… | J40: =AI20 -> Michigan can win a game in regular time, not make-believe time…
B43: Get Unique Selection Number
B44: =B24 -> Away | C44: =C24 -> Home | D44: =D24 -> Under | E44: =E24 -> Over | G44: =G24 -> Away | H44: =H24 -> Home | I44: =I24 -> Under | J44: =J24 -> Over
B45: =IF(ISBLANK(Sheet1!K7),0,1) -> 0 | C45: =IF(ISBLANK(Sheet1!L7),B45,B45+1) -> 0 | D45: =IF(ISBLANK(Sheet1!M7),C45,C45+1) -> 0 | E45: =IF(ISBLANK(Sheet1!N7),D45,D45+1) -> 0 | G45: =IF(B45=1,1,0) -> 0 | H45: =IF(C45=B45,0,C45) -> 0 | I45: =IF(D45=C45,0,D45) -> 0 | J45: =IF(E45=D45,0,E45) -> 0
B46: =IF(ISBLANK(Sheet1!K8),E45,E45+1) -> 0 | C46: =IF(ISBLANK(Sheet1!L8),B46,B46+1) -> 0 | D46: =IF(ISBLANK(Sheet1!M8),C46,C46+1) -> 0 | E46: =IF(ISBLANK(Sheet1!N8),D46,D46+1) -> 0 | G46: =IF(B46=E45,0,B46) -> 0 | H46: =IF(C46=B46,0,C46) -> 0 | I46: =IF(D46=C46,0,D46) -> 0 | J46: =IF(E46=D46,0,E46) -> 0
B47: =IF(ISBLANK(Sheet1!K9),E46,E46+1) -> 0 | C47: =IF(ISBLANK(Sheet1!L9),B47,B47+1) -> 0 | D47: =IF(ISBLANK(Sheet1!M9),C47,C47+1) -> 0 | E47: =IF(ISBLANK(Sheet1!N9),D47,D47+1) -> 0 | G47: =IF(B47=E46,0,B47) -> 0 | H47: =IF(C47=B47,0,C47) -> 0 | I47: =IF(D47=C47,0,D47) -> 0 | J47: =IF(E47=D47,0,E47) -> 0
B48: =IF(ISBLANK(Sheet1!K10),E47,E47+1) -> 0 | C48: =IF(ISBLANK(Sheet1!L10),B48,B48+1) -> 0 | D48: =IF(ISBLANK(Sheet1!M10),C48,C48+1) -> 0 | E48: =IF(ISBLANK(Sheet1!N10),D48,D48+1) -> 0 | G48: =IF(B48=E47,0,B48) -> 0 | H48: =IF(C48=B48,0,C48) -> 0 | I48: =IF(D48=C48,0,D48) -> 0 | J48: =IF(E48=D48,0,E48) -> 0
B49: =IF(ISBLANK(Sheet1!K11),E48,E48+1) -> 0 | C49: =IF(ISBLANK(Sheet1!L11),B49,B49+1) -> 0 | D49: =IF(ISBLANK(Sheet1!M11),C49,C49+1) -> 0 | E49: =IF(ISBLANK(Sheet1!N11),D49,D49+1) -> 0 | G49: =IF(B49=E48,0,B49) -> 0 | H49: =IF(C49=B49,0,C49) -> 0 | I49: =IF(D49=C49,0,D49) -> 0 | J49: =IF(E49=D49,0,E49) -> 0
B50: =IF(ISBLANK(Sheet1!K12),E49,E49+1) -> 0 | C50: =IF(ISBLANK(Sheet1!L12),B50,B50+1) -> 0 | D50: =IF(ISBLANK(Sheet1!M12),C50,C50+1) -> 0 | E50: =IF(ISBLANK(Sheet1!N12),D50,D50+1) -> 0 | G50: =IF(B50=E49,0,B50) -> 0 | H50: =IF(C50=B50,0,C50) -> 0 | I50: =IF(D50=C50,0,D50) -> 0 | J50: =IF(E50=D50,0,E50) -> 0
B51: =IF(ISBLANK(Sheet1!K13),E50,E50+1) -> 0 | C51: =IF(ISBLANK(Sheet1!L13),B51,B51+1) -> 0 | D51: =IF(ISBLANK(Sheet1!M13),C51,C51+1) -> 0 | E51: =IF(ISBLANK(Sheet1!N13),D51,D51+1) -> 0 | G51: =IF(B51=E50,0,B51) -> 0 | H51: =IF(C51=B51,0,C51) -> 0 | I51: =IF(D51=C51,0,D51) -> 0 | J51: =IF(E51=D51,0,E51) -> 0
...

Sheet line_desc
A1: Line | B1: Away Win | C1: Home Win | D1: Push
A2: -50 | B2: ="Away win, tie, or Home win by "&ABS(A2)-1&" or less" -> Away win, tie, or Home win by 49 or less | C2: ="Home win by "&ABS(A2)+1&" or more" -> Home win by 51 or more | D2: ="Home win by "&ABS(A2) -> Home win by 50
A3: =A2+1 -> -49 | B3: ="Away win, tie, or Home win by "&ABS(A3)-1&" or less" -> Away win, tie, or Home win by 48 or less | C3: ="Home win by "&ABS(A3)+1&" or more" -> Home win by 50 or more | D3: ="Home win by "&ABS(A3) -> Home win by 49
A4: =A3+1 -> -48 | B4: ="Away win, tie, or Home win by "&ABS(A4)-1&" or less" -> Away win, tie, or Home win by 47 or less | C4: ="Home win by "&ABS(A4)+1&" or more" -> Home win by 49 or more | D4: ="Home win by "&ABS(A4) -> Home win by 48
A5: =A4+1 -> -47 | B5: ="Away win, tie, or Home win by "&ABS(A5)-1&" or less" -> Away win, tie, or Home win by 46 or less | C5: ="Home win by "&ABS(A5)+1&" or more" -> Home win by 48 or more | D5: ="Home win by "&ABS(A5) -> Home win by 47
A6: =A5+1 -> -46 | B6: ="Away win, tie, or Home win by "&ABS(A6)-1&" or less" -> Away win, tie, or Home win by 45 or less | C6: ="Home win by "&ABS(A6)+1&" or more" -> Home win by 47 or more | D6: ="Home win by "&ABS(A6) -> Home win by 46
A7: =A6+1 -> -45 | B7: ="Away win, tie, or Home win by "&ABS(A7)-1&" or less" -> Away win, tie, or Home win by 44 or less | C7: ="Home win by "&ABS(A7)+1&" or more" -> Home win by 46 or more | D7: ="Home win by "&ABS(A7) -> Home win by 45
A8: =A7+1 -> -44 | B8: ="Away win, tie, or Home win by "&ABS(A8)-1&" or less" -> Away win, tie, or Home win by 43 or less | C8: ="Home win by "&ABS(A8)+1&" or more" -> Home win by 45 or more | D8: ="Home win by "&ABS(A8) -> Home win by 44
A9: =A8+1 -> -43 | B9: ="Away win, tie, or Home win by "&ABS(A9)-1&" or less" -> Away win, tie, or Home win by 42 or less | C9: ="Home win by "&ABS(A9)+1&" or more" -> Home win by 44 or more | D9: ="Home win by "&ABS(A9) -> Home win by 43
A10: =A9+1 -> -42 | B10: ="Away win, tie, or Home win by "&ABS(A10)-1&" or less" -> Away win, tie, or Home win by 41 or less | C10: ="Home win by "&ABS(A10)+1&" or more" -> Home win by 43 or more | D10: ="Home win by "&ABS(A10) -> Home win by 42
A11: =A10+1 -> -41 | B11: ="Away win, tie, or Home win by "&ABS(A11)-1&" or less" -> Away win, tie, or Home win by 40 or less | C11: ="Home win by "&ABS(A11)+1&" or more" -> Home win by 42 or more | D11: ="Home win by "&ABS(A11) -> Home win by 41
A12: =A11+1 -> -40 | B12: ="Away win, tie, or Home win by "&ABS(A12)-1&" or less" -> Away win, tie, or Home win by 39 or less | C12: ="Home win by "&ABS(A12)+1&" or more" -> Home win by 41 or more | D12: ="Home win by "&ABS(A12) -> Home win by 40
A13: =A12+1 -> -39 | B13: ="Away win, tie, or Home win by "&ABS(A13)-1&" or less" -> Away win, tie, or Home win by 38 or less | C13: ="Home win by "&ABS(A13)+1&" or more" -> Home win by 40 or more | D13: ="Home win by "&ABS(A13) -> Home win by 39
A14: =A13+1 -> -38 | B14: ="Away win, tie, or Home win by "&ABS(A14)-1&" or less" -> Away win, tie, or Home win by 37 or less | C14: ="Home win by "&ABS(A14)+1&" or more" -> Home win by 39 or more | D14: ="Home win by "&ABS(A14) -> Home win by 38
... A49: =A48+1 -> -3 | B49: ="Away win, tie, or Home win by "&ABS(A49)-1&" or less" -> Away win, tie, or Home win by 2 or less | C49: ="Home win by "&ABS(A49)+1&" or more" -> Home win by 4 or more | D49: ="Home win by "&ABS(A49) -> Home win by 3
A50: =A49+1 -> -2 | B50: Away win, tie, or Home win by 1 | C50: ="Home win by "&ABS(A50)+1&" or more" -> Home win by 3 or more | D50: ="Home win by "&ABS(A50) -> Home win by 2
A51: =A50+1 -> -1 | B51: Away win or tie | C51: ="Home win by "&ABS(A51)+1&" or more" -> Home win by 2 or more | D51: ="Home win by "&ABS(A51) -> Home win by 1
A52: =A51+1 -> 0 | B52: Away win | C52: Home win | D52: Home tie Away
A53: =A52+1 -> 1 | B53: ="Away win by "&ABS(A53)+1&" or more" -> Away win by 2 or more | C53: Home win or tie | D53: ="Away win by "&ABS(A53) -> Away win by 1
A54: =A53+1 -> 2 | B54: ="Away win by "&ABS(A54)+1&" or more" -> Away win by 3 or more | C54: Home win, tie, or Away win by 1 | D54: ="Away win by "&ABS(A54) -> Away win by 2
A55: =A54+1 -> 3 | B55: ="Away win by "&ABS(A55)+1&" or more" -> Away win by 4 or more | C55: ="Home win, tie, or Away win by "&ABS(A55)-1&" or less" -> Home win, tie, or Away win by 2 or less | D55: ="Away win by "&ABS(A55) -> Away win by 3
A56: =A55+1 -> 4 | B56: ="Away win by "&ABS(A56)+1&" or more" -> Away win by 5 or more | C56: ="Home win, tie, or Away win by "&ABS(A56)-1&" or less" -> Home win, tie, or Away win by 3 or less | D56: ="Away win by "&ABS(A56) -> Away win by 4
A57: =A56+1 -> 5 | B57: ="Away win by "&ABS(A57)+1&" or more" -> Away win by 6 or more | C57: ="Home win, tie, or Away win by "&ABS(A57)-1&" or less" -> Home win, tie, or Away win by 4 or less | D57: ="Away win by "&ABS(A57) -> Away win by 5
A58: =A57+1 -> 6 | B58: ="Away win by "&ABS(A58)+1&" or more" -> Away win by 7 or more | C58: ="Home win, tie, or Away win by "&ABS(A58)-1&" or less" -> Home win, tie, or Away win by 5 or less | D58: ="Away win by "&ABS(A58) -> Away win by 6
A59: =A58+1 -> 7 | B59: ="Away win by "&ABS(A59)+1&" or more" -> Away win by 8 or more | C59: ="Home win, tie, or Away win by "&ABS(A59)-1&" or less" -> Home win, tie, or Away win by 6 or less | D59: ="Away win by "&ABS(A59) -> Away win by 7
A60: =A59+1 -> 8 | B60: ="Away win by "&ABS(A60)+1&" or more" -> Away win by 9 or more | C60: ="Home win, tie, or Away win by "&ABS(A60)-1&" or less" -> Home win, tie, or Away win by 7 or less | D60: ="Away win by "&ABS(A60) -> Away win by 8
A61: =A60+1 -> 9 | B61: ="Away win by "&ABS(A61)+1&" or more" -> Away win by 10 or more | C61: ="Home win, tie, or Away win by "&ABS(A61)-1&" or less" -> Home win, tie, or Away win by 8 or less | D61: ="Away win by "&ABS(A61) -> Away win by 9
A62: =A61+1 -> 10 | B62: ="Away win by "&ABS(A62)+1&" or more" -> Away win by 11 or more | C62: ="Home win, tie, or Away win by "&ABS(A62)-1&" or less" -> Home win, tie, or Away win by 9 or less | D62: ="Away win by "&ABS(A62) -> Away win by 10
A63: =A62+1 -> 11 | B63: ="Away win by "&ABS(A63)+1&" or more" -> Away win by 12 or more | C63: ="Home win, tie, or Away win by "&ABS(A63)-1&" or less" -> Home win, tie, or Away win by 10 or less | D63: ="Away win by "&ABS(A63) -> Away win by 11
A64: =A63+1 -> 12 | B64: ="Away win by "&ABS(A64)+1&" or more" -> Away win by 13 or more | C64: ="Home win, tie, or Away win by "&ABS(A64)-1&" or less" -> Home win, tie, or Away win by 11 or less | D64: ="Away win by "&ABS(A64) -> Away win by 12
A65: =A64+1 -> 13 | B65: ="Away win by "&ABS(A65)+1&" or more" -> Away win by 14 or more | C65: ="Home win, tie, or Away win by "&ABS(A65)-1&" or less" -> Home win, tie, or Away win by 12 or less | D65: ="Away win by "&ABS(A65) -> Away win by 13
A66: =A65+1 -> 14 | B66: ="Away win by "&ABS(A66)+1&" or more" -> Away win by 15 or more | C66: ="Home win, tie, or Away win by "&ABS(A66)-1&" or less" -> Home win, tie, or Away win by 13 or less | D66: ="Away win by "&ABS(A66) -> Away win by 14
... A102: =A101+1 -> 50 | B102: ="Away win by "&ABS(A102)+1&" or more" -> Away win by 51 or more | C102: ="Home win, tie, or Away win by "&ABS(A102)-1&" or less" -> Home win, tie, or Away win by 49 or less | D102: ="Away win by "&ABS(A102) -> Away win by 50
A104: -50.5 | B104: ="Away win, tie, or Home win by "&ABS(INT(A104))-1&" or less" -> Away win, tie, or Home win by 50 or less | C104: ="Home win by "&ABS(INT(A104))&" or more" -> Home win by 51 or more | D104: =impossible -> Michigan can win a game in regular time, not make-believe time…
